<mujoco model="aic_world">
  <compiler angle="radian" />

  <option gravity="0 0 -9.8" magnetic="5.5645e-06 2.28758e-05 -4.23884e-05" />

  <visual>
    <global offwidth="1152" offheight="1024" />
    <headlight ambient="0 0 0" diffuse="0 0 0" specular="0 0 0" />
    <map znear="0.0025" />
  </visual>

  <default>
    <default class="robot_unused" />
  </default>

  <asset>
    <material name="material_2526a91bb24bdc844d851a8061563c5c49b4bfe1445f84f9fcebda7b03d12c17_base_eSeries_UR5e_013-mesh" class="robot_unused" shininess="30" rgba="0.278431 0.278431 0.278431 1" />
    <material name="material_2526a91bb24bdc844d851a8061563c5c49b4bfe1445f84f9fcebda7b03d12c17_base_eSeries_UR5e_066-mesh" class="robot_unused" shininess="30" rgba="0.0313726 0.0313726 0.0313726 1" />
    <material name="material_2526a91bb24bdc844d851a8061563c5c49b4bfe1445f84f9fcebda7b03d12c17_shoulder_eSeries_UR5e_001-mesh" class="robot_unused" shininess="30" rgba="0.278431 0.278431 0.278431 1" />
    <material name="material_2526a91bb24bdc844d851a8061563c5c49b4bfe1445f84f9fcebda7b03d12c17_shoulder_eSeries_UR5e_067-mesh" class="robot_unused" shininess="30" rgba="0.0313726 0.0313726 0.0313726 1" />
    <material name="material_2526a91bb24bdc844d851a8061563c5c49b4bfe1445f84f9fcebda7b03d12c17_shoulder_eSeries_UR5e_068-mesh" class="robot_unused" shininess="30" rgba="0.490196 0.678431 0.8 1" />
    <material name="material_2526a91bb24bdc844d851a8061563c5c49b4bfe1445f84f9fcebda7b03d12c17_upperarm_merged_0" class="robot_unused" shininess="30" rgba="0.490196 0.678431 0.8 1" />
    <material name="material_2526a91bb24bdc844d851a8061563c5c49b4bfe1445f84f9fcebda7b03d12c17_upperarm_merged_1" class="robot_unused" shininess="30" rgba="0.278431 0.278431 0.278431 1" />
    <material name="material_2526a91bb24bdc844d851a8061563c5c49b4bfe1445f84f9fcebda7b03d12c17_upperarm_merged_2" class="robot_unused" shininess="30" rgba="0.0313726 0.0313726 0.0313726 1" />
    <material name="material_2526a91bb24bdc844d851a8061563c5c49b4bfe1445f84f9fcebda7b03d12c17_upperarm_eSeries_UR5e_073-mesh" class="robot_unused" shininess="30" rgba="0.819608 0.819608 0.819608 1" />
    <material name="material_2526a91bb24bdc844d851a8061563c5c49b4bfe1445f84f9fcebda7b03d12c17_forearm_merged_0" class="robot_unused" shininess="30" rgba="0.278431 0.278431 0.278431 1" />
    <material name="material_2526a91bb24bdc844d851a8061563c5c49b4bfe1445f84f9fcebda7b03d12c17_forearm_merged_1" class="robot_unused" shininess="30" rgba="0.0313726 0.0313726 0.0313726 1" />
    <material name="material_2526a91bb24bdc844d851a8061563c5c49b4bfe1445f84f9fcebda7b03d12c17_forearm_eSeries_UR5e_079-mesh" class="robot_unused" shininess="30" rgba="0.819608 0.819608 0.819608 1" />
    <material name="material_2526a91bb24bdc844d851a8061563c5c49b4bfe1445f84f9fcebda7b03d12c17_forearm_eSeries_UR5e_081-mesh" class="robot_unused" shininess="30" rgba="0.490196 0.678431 0.8 1" />
    <material name="material_2526a91bb24bdc844d851a8061563c5c49b4bfe1445f84f9fcebda7b03d12c17_wrist1_eSeries_UR5e_043-mesh" class="robot_unused" shininess="30" rgba="0.278431 0.278431 0.278431 1" />
    <material name="material_2526a91bb24bdc844d851a8061563c5c49b4bfe1445f84f9fcebda7b03d12c17_wrist1_eSeries_UR5e_083-mesh" class="robot_unused" shininess="30" rgba="0.490196 0.678431 0.8 1" />
    <material name="material_2526a91bb24bdc844d851a8061563c5c49b4bfe1445f84f9fcebda7b03d12c17_wrist1_eSeries_UR5e_084-mesh" class="robot_unused" shininess="30" rgba="0.0313726 0.0313726 0.0313726 1" />
    <material name="material_2526a91bb24bdc844d851a8061563c5c49b4bfe1445f84f9fcebda7b03d12c17_wrist2_eSeries_UR5e_049-mesh" class="robot_unused" shininess="30" rgba="0.278431 0.278431 0.278431 1" />
    <material name="material_2526a91bb24bdc844d851a8061563c5c49b4bfe1445f84f9fcebda7b03d12c17_wrist2_eSeries_UR5e_085-mesh" class="robot_unused" shininess="30" rgba="0.490196 0.678431 0.8 1" />
    <material name="material_2526a91bb24bdc844d851a8061563c5c49b4bfe1445f84f9fcebda7b03d12c17_wrist2_eSeries_UR5e_086-mesh" class="robot_unused" shininess="30" rgba="0.0313726 0.0313726 0.0313726 1" />
    <material name="material_2526a91bb24bdc844d851a8061563c5c49b4bfe1445f84f9fcebda7b03d12c17_wrist3_eSeries_UR5e_058-mesh" class="robot_unused" shininess="30" rgba="0.819608 0.819608 0.819608 1" />
    <material name="material_9883659ad3e180e4613cb31e888868fb6599c2975f7d6bb9ef140bf2782bae64_cam_mount_visual_Cam_Mount.001" class="robot_unused" shininess="30" rgba="0.913725 0.913725 0.921569 1" />
    <material name="material_9883659ad3e180e4613cb31e888868fb6599c2975f7d6bb9ef140bf2782bae64_cam_mount_visual_Cam_Mount.001_1" class="robot_unused" shininess="30" rgba="0.8 0.8 0.8 1" />
    <material name="material_479655a6843b0953e26a94d9816615add694660aa31c6c93a9863e851478702a_basler_cam_visual_59871rev000.001" class="robot_unused" shininess="30" rgba="0.00784314 0.00784314 0.00784314 1" />
    <material name="material_479655a6843b0953e26a94d9816615add694660aa31c6c93a9863e851478702a_basler_cam_visual_59871rev000.001_1" class="robot_unused" shininess="30" rgba="0.8 0.8 0.8 1" />
    <material name="material_479655a6843b0953e26a94d9816615add694660aa31c6c93a9863e851478702a_basler_cam_visual_59871rev000.001_2" class="robot_unused" shininess="30" rgba="0.0196078 0.0196078 0.0196078 1" />
    <material name="material_479655a6843b0953e26a94d9816615add694660aa31c6c93a9863e851478702a_basler_cam_visual_59871rev000.001_3" class="robot_unused" shininess="30" rgba="0.00392157 0.00392157 0.00392157 1" />
    <material name="material_479655a6843b0953e26a94d9816615add694660aa31c6c93a9863e851478702a_basler_cam_visual_59871rev000.001_4" class="robot_unused" shininess="30" rgba="0.52549 0.52549 0.52549 1" />
    <material name="material_a0d54315167580a143651a5a9d7963d83b0b7f25767ad4d48d4d3230ded1362f_axia_ft_sensor_visual_Axia80_M20.001" class="robot_unused" shininess="30" rgba="0.882353 0.792157 0.713726 1" />
    <material name="material_a0d54315167580a143651a5a9d7963d83b0b7f25767ad4d48d4d3230ded1362f_axia_ft_sensor_visual_Axia80_M20.001_1" class="robot_unused" shininess="30" rgba="0.0196078 0.0196078 0.0196078 1" />
    <material name="material_a0d54315167580a143651a5a9d7963d83b0b7f25767ad4d48d4d3230ded1362f_axia_ft_sensor_visual_Axia80_M20.001_2" class="robot_unused" shininess="30" rgba="0.8 0.564706 0.188235 1" />
    <material name="material_a0d54315167580a143651a5a9d7963d83b0b7f25767ad4d48d4d3230ded1362f_axia_ft_sensor_visual_Axia80_M20.001_3" class="robot_unused" shininess="30" rgba="0.768627 0.811765 0.627451 1" />
    <material name="material_a0d54315167580a143651a5a9d7963d83b0b7f25767ad4d48d4d3230ded1362f_axia_ft_sensor_visual_Axia80_M20.001_4" class="robot_unused" shininess="30" rgba="0.0117647 0.0117647 0.0117647 1" />
    <material name="material_354908445af88fcf1366e0e4d2bd23726354cdb419dd151b3c01461be6e77331_hande_base_visual_Cylinder.004" class="robot_unused" shininess="30" rgba="0.913725 0.913725 0.921569 1" />
    <material name="material_354908445af88fcf1366e0e4d2bd23726354cdb419dd151b3c01461be6e77331_hande_base_visual_Cylinder.004_1" class="robot_unused" shininess="30" rgba="0.00392157 0.00392157 0.00392157 1" />
    <material name="material_354908445af88fcf1366e0e4d2bd23726354cdb419dd151b3c01461be6e77331_hande_base_visual_Cylinder.004_2" class="robot_unused" shininess="30" rgba="0.784314 0.823529 0.847059 1" />
    <material name="material_354908445af88fcf1366e0e4d2bd23726354cdb419dd151b3c01461be6e77331_hande_base_visual_Cylinder.004_3" class="robot_unused" shininess="30" rgba="0.0117647 0.0117647 0.0117647 1" />
    <material name="material_354908445af88fcf1366e0e4d2bd23726354cdb419dd151b3c01461be6e77331_hande_base_visual_Cylinder.004_4" class="robot_unused" shininess="30" rgba="0.00784314 0.00784314 0.00784314 1" />
    <material name="material_354908445af88fcf1366e0e4d2bd23726354cdb419dd151b3c01461be6e77331_hande_base_visual_Cylinder.004_5" class="robot_unused" shininess="30" rgba="0.203922 0.203922 0.203922 1" />
    <material name="material_354908445af88fcf1366e0e4d2bd23726354cdb419dd151b3c01461be6e77331_hande_base_visual_Cylinder.004_6" class="robot_unused" shininess="30" rgba="0.5 0.5 0.5 1" />
    <material name="material_354908445af88fcf1366e0e4d2bd23726354cdb419dd151b3c01461be6e77331_hande_finger_visual_Finger.001" class="robot_unused" shininess="30" rgba="0.8 0.8 0.8 1" />
    <mesh name="f5ca357fee34c8a14fc8cf256a0c3217c1d95fdfcd83df086610df08316e0b6a_base.stl" class="robot_unused" content_type="model/stl" file="meshes/ur5e_base.stl" />
    <mesh name="2526a91bb24bdc844d851a8061563c5c49b4bfe1445f84f9fcebda7b03d12c17_base_eSeries_UR5e_013-mesh" class="robot_unused" content_type="model/obj" file="meshes/ur5e_base__eSeries_UR5e_013-mesh.obj" inertia="shell" />
    <mesh name="2526a91bb24bdc844d851a8061563c5c49b4bfe1445f84f9fcebda7b03d12c17_base_eSeries_UR5e_066-mesh" class="robot_unused" content_type="model/obj" file="meshes/ur5e_base__eSeries_UR5e_066-mesh.obj" inertia="shell" />
    <mesh name="f5ca357fee34c8a14fc8cf256a0c3217c1d95fdfcd83df086610df08316e0b6a_shoulder.stl" class="robot_unused" content_type="model/stl" file="meshes/ur5e_shoulder.stl" />
    <mesh name="2526a91bb24bdc844d851a8061563c5c49b4bfe1445f84f9fcebda7b03d12c17_shoulder_eSeries_UR5e_001-mesh" class="robot_unused" content_type="model/obj" file="meshes/ur5e_shoulder__eSeries_UR5e_001-mesh.obj" inertia="shell" />
    <mesh name="2526a91bb24bdc844d851a8061563c5c49b4bfe1445f84f9fcebda7b03d12c17_shoulder_eSeries_UR5e_067-mesh" class="robot_unused" content_type="model/obj" file="meshes/ur5e_shoulder__eSeries_UR5e_067-mesh.obj" inertia="shell" />
    <mesh name="2526a91bb24bdc844d851a8061563c5c49b4bfe1445f84f9fcebda7b03d12c17_shoulder_eSeries_UR5e_068-mesh" class="robot_unused" content_type="model/obj" file="meshes/ur5e_shoulder__eSeries_UR5e_068-mesh.obj" inertia="shell" />
    <mesh name="f5ca357fee34c8a14fc8cf256a0c3217c1d95fdfcd83df086610df08316e0b6a_upperarm.stl" class="robot_unused" content_type="model/stl" file="meshes/ur5e_upperarm.stl" />
    <mesh name="2526a91bb24bdc844d851a8061563c5c49b4bfe1445f84f9fcebda7b03d12c17_upperarm_merged_0" class="robot_unused" content_type="model/obj" file="meshes/ur5e_upperarm__merged_0.obj" inertia="shell" />
    <mesh name="2526a91bb24bdc844d851a8061563c5c49b4bfe1445f84f9fcebda7b03d12c17_upperarm_merged_1" class="robot_unused" content_type="model/obj" file="meshes/ur5e_upperarm__merged_1.obj" inertia="shell" />
    <mesh name="2526a91bb24bdc844d851a8061563c5c49b4bfe1445f84f9fcebda7b03d12c17_upperarm_merged_2" class="robot_unused" content_type="model/obj" file="meshes/ur5e_upperarm__merged_2.obj" inertia="shell" />
    <mesh name="2526a91bb24bdc844d851a8061563c5c49b4bfe1445f84f9fcebda7b03d12c17_upperarm_eSeries_UR5e_073-mesh" class="robot_unused" content_type="model/obj" file="meshes/ur5e_upperarm__eSeries_UR5e_073-mesh.obj" inertia="shell" />
    <mesh name="f5ca357fee34c8a14fc8cf256a0c3217c1d95fdfcd83df086610df08316e0b6a_forearm.stl" class="robot_unused" content_type="model/stl" file="meshes/ur5e_forearm.stl" />
    <mesh name="2526a91bb24bdc844d851a8061563c5c49b4bfe1445f84f9fcebda7b03d12c17_forearm_merged_0" class="robot_unused" content_type="model/obj" file="meshes/ur5e_forearm__merged_0.obj" inertia="shell" />
    <mesh name="2526a91bb24bdc844d851a8061563c5c49b4bfe1445f84f9fcebda7b03d12c17_forearm_merged_1" class="robot_unused" content_type="model/obj" file="meshes/ur5e_forearm__merged_1.obj" inertia="shell" />
    <mesh name="2526a91bb24bdc844d851a8061563c5c49b4bfe1445f84f9fcebda7b03d12c17_forearm_eSeries_UR5e_079-mesh" class="robot_unused" content_type="model/obj" file="meshes/ur5e_forearm__eSeries_UR5e_079-mesh.obj" inertia="shell" />
    <mesh name="2526a91bb24bdc844d851a8061563c5c49b4bfe1445f84f9fcebda7b03d12c17_forearm_eSeries_UR5e_081-mesh" class="robot_unused" content_type="model/obj" file="meshes/ur5e_forearm__eSeries_UR5e_081-mesh.obj" inertia="shell" />
    <mesh name="f5ca357fee34c8a14fc8cf256a0c3217c1d95fdfcd83df086610df08316e0b6a_wrist1.stl" class="robot_unused" content_type="model/stl" file="meshes/ur5e_wrist1.stl" />
    <mesh name="2526a91bb24bdc844d851a8061563c5c49b4bfe1445f84f9fcebda7b03d12c17_wrist1_eSeries_UR5e_043-mesh" class="robot_unused" content_type="model/obj" file="meshes/ur5e_wrist1__eSeries_UR5e_043-mesh.obj" inertia="shell" />
    <mesh name="2526a91bb24bdc844d851a8061563c5c49b4bfe1445f84f9fcebda7b03d12c17_wrist1_eSeries_UR5e_083-mesh" class="robot_unused" content_type="model/obj" file="meshes/ur5e_wrist1__eSeries_UR5e_083-mesh.obj" inertia="shell" />
    <mesh name="2526a91bb24bdc844d851a8061563c5c49b4bfe1445f84f9fcebda7b03d12c17_wrist1_eSeries_UR5e_084-mesh" class="robot_unused" content_type="model/obj" file="meshes/ur5e_wrist1__eSeries_UR5e_084-mesh.obj" inertia="shell" />
    <mesh name="f5ca357fee34c8a14fc8cf256a0c3217c1d95fdfcd83df086610df08316e0b6a_wrist2.stl" class="robot_unused" content_type="model/stl" file="meshes/ur5e_wrist2.stl" />
    <mesh name="2526a91bb24bdc844d851a8061563c5c49b4bfe1445f84f9fcebda7b03d12c17_wrist2_eSeries_UR5e_049-mesh" class="robot_unused" content_type="model/obj" file="meshes/ur5e_wrist2__eSeries_UR5e_049-mesh.obj" inertia="shell" />
    <mesh name="2526a91bb24bdc844d851a8061563c5c49b4bfe1445f84f9fcebda7b03d12c17_wrist2_eSeries_UR5e_085-mesh" class="robot_unused" content_type="model/obj" file="meshes/ur5e_wrist2__eSeries_UR5e_085-mesh.obj" inertia="shell" />
    <mesh name="2526a91bb24bdc844d851a8061563c5c49b4bfe1445f84f9fcebda7b03d12c17_wrist2_eSeries_UR5e_086-mesh" class="robot_unused" content_type="model/obj" file="meshes/ur5e_wrist2__eSeries_UR5e_086-mesh.obj" inertia="shell" />
    <mesh name="f5ca357fee34c8a14fc8cf256a0c3217c1d95fdfcd83df086610df08316e0b6a_wrist3.stl" class="robot_unused" content_type="model/stl" file="meshes/ur5e_wrist3.stl" />
    <mesh name="2526a91bb24bdc844d851a8061563c5c49b4bfe1445f84f9fcebda7b03d12c17_wrist3_eSeries_UR5e_058-mesh" class="robot_unused" content_type="model/obj" file="meshes/ur5e_wrist3__eSeries_UR5e_058-mesh.obj" inertia="shell" />
    <mesh name="9883659ad3e180e4613cb31e888868fb6599c2975f7d6bb9ef140bf2782bae64_cam_mount_visual_Cam_Mount.001" class="robot_unused" content_type="model/obj" file="meshes/cam_mount_visual__Cam_Mount.001.obj" inertia="shell" />
    <mesh name="9883659ad3e180e4613cb31e888868fb6599c2975f7d6bb9ef140bf2782bae64_cam_mount_visual_Cam_Mount.001_1" class="robot_unused" content_type="model/obj" file="meshes/cam_mount_visual__Cam_Mount.001_1.obj" inertia="shell" />
    <mesh name="479655a6843b0953e26a94d9816615add694660aa31c6c93a9863e851478702a_basler_cam_visual_59871rev000.001" class="robot_unused" content_type="model/obj" file="meshes/basler_cam_visual__59871rev000.001.obj" inertia="shell" />
    <mesh name="479655a6843b0953e26a94d9816615add694660aa31c6c93a9863e851478702a_basler_cam_visual_59871rev000.001_1" class="robot_unused" content_type="model/obj" file="meshes/basler_cam_visual__59871rev000.001_1.obj" inertia="shell" />
    <mesh name="479655a6843b0953e26a94d9816615add694660aa31c6c93a9863e851478702a_basler_cam_visual_59871rev000.001_2" class="robot_unused" content_type="model/obj" file="meshes/basler_cam_visual__59871rev000.001_2.obj" inertia="shell" />
    <mesh name="479655a6843b0953e26a94d9816615add694660aa31c6c93a9863e851478702a_basler_cam_visual_59871rev000.001_3" class="robot_unused" content_type="model/obj" file="meshes/basler_cam_visual__59871rev000.001_3.obj" inertia="shell" />
    <mesh name="479655a6843b0953e26a94d9816615add694660aa31c6c93a9863e851478702a_basler_cam_visual_59871rev000.001_4" class="robot_unused" content_type="model/obj" file="meshes/basler_cam_visual__59871rev000.001_4.obj" inertia="shell" />
    <mesh name="a0d54315167580a143651a5a9d7963d83b0b7f25767ad4d48d4d3230ded1362f_axia_ft_sensor_visual_Axia80_M20.001" class="robot_unused" content_type="model/obj" file="meshes/axia_ft_sensor_visual__Axia80_M20.001.obj" inertia="shell" />
    <mesh name="a0d54315167580a143651a5a9d7963d83b0b7f25767ad4d48d4d3230ded1362f_axia_ft_sensor_visual_Axia80_M20.001_1" class="robot_unused" content_type="model/obj" file="meshes/axia_ft_sensor_visual__Axia80_M20.001_1.obj" inertia="shell" />
    <mesh name="a0d54315167580a143651a5a9d7963d83b0b7f25767ad4d48d4d3230ded1362f_axia_ft_sensor_visual_Axia80_M20.001_2" class="robot_unused" content_type="model/obj" file="meshes/axia_ft_sensor_visual__Axia80_M20.001_2.obj" inertia="shell" />
    <mesh name="a0d54315167580a143651a5a9d7963d83b0b7f25767ad4d48d4d3230ded1362f_axia_ft_sensor_visual_Axia80_M20.001_3" class="robot_unused" content_type="model/obj" file="meshes/axia_ft_sensor_visual__Axia80_M20.001_3.obj" inertia="shell" />
    <mesh name="a0d54315167580a143651a5a9d7963d83b0b7f25767ad4d48d4d3230ded1362f_axia_ft_sensor_visual_Axia80_M20.001_4" class="robot_unused" content_type="model/obj" file="meshes/axia_ft_sensor_visual__Axia80_M20.001_4.obj" inertia="shell" />
    <mesh name="354908445af88fcf1366e0e4d2bd23726354cdb419dd151b3c01461be6e77331_hande_base_visual_Cylinder.004" class="robot_unused" content_type="model/obj" file="meshes/hande_base_visual__Cylinder.004.obj" inertia="shell" />
    <mesh name="354908445af88fcf1366e0e4d2bd23726354cdb419dd151b3c01461be6e77331_hande_base_visual_Cylinder.004_1" class="robot_unused" content_type="model/obj" file="meshes/hande_base_visual__Cylinder.004_1.obj" inertia="shell" />
    <mesh name="354908445af88fcf1366e0e4d2bd23726354cdb419dd151b3c01461be6e77331_hande_base_visual_Cylinder.004_2" class="robot_unused" content_type="model/obj" file="meshes/hande_base_visual__Cylinder.004_2.obj" inertia="shell" />
    <mesh name="354908445af88fcf1366e0e4d2bd23726354cdb419dd151b3c01461be6e77331_hande_base_visual_Cylinder.004_3" class="robot_unused" content_type="model/obj" file="meshes/hande_base_visual__Cylinder.004_3.obj" inertia="shell" />
    <mesh name="354908445af88fcf1366e0e4d2bd23726354cdb419dd151b3c01461be6e77331_hande_base_visual_Cylinder.004_4" class="robot_unused" content_type="model/obj" file="meshes/hande_base_visual__Cylinder.004_4.obj" inertia="shell" />
    <mesh name="354908445af88fcf1366e0e4d2bd23726354cdb419dd151b3c01461be6e77331_hande_base_visual_Cylinder.004_5" class="robot_unused" content_type="model/obj" file="meshes/hande_base_visual__Cylinder.004_5.obj" inertia="shell" />
    <mesh name="354908445af88fcf1366e0e4d2bd23726354cdb419dd151b3c01461be6e77331_hande_base_visual_Cylinder.004_6" class="robot_unused" content_type="model/obj" file="meshes/hande_base_visual__Cylinder.004_6.obj" inertia="shell" />
    <mesh name="354908445af88fcf1366e0e4d2bd23726354cdb419dd151b3c01461be6e77331_hande_finger_visual_Finger.001" class="robot_unused" content_type="model/obj" file="meshes/hande_finger_visual__Finger.001.obj" inertia="shell" />
  </asset>

  <worldbody>
    <body name="tabletop" gravcomp="1" pos="-0.2 0.2 1.14" quat="1 0 0 0">
      <inertial pos="0 0 0" quat="0.5 0.5 -0.5 0.5" mass="4" diaginertia="0.0072 0.00443333 0.00443333" />
      <geom name="table_surface" type="box" size="0.75 0.75 0.005" pos="0.2 -0.2 -0.005" rgba="0.3 0.3 0.3 0" group="3" />
      <geom name="tabletop_fixed_joint_lump__base_link_inertia_collision" class="robot_unused" type="mesh" group="3" mesh="f5ca357fee34c8a14fc8cf256a0c3217c1d95fdfcd83df086610df08316e0b6a_base.stl" />
      <geom name="tabletop_fixed_joint_lump__base_link_inertia_visual" class="robot_unused" type="mesh" contype="0" conaffinity="0" material="material_2526a91bb24bdc844d851a8061563c5c49b4bfe1445f84f9fcebda7b03d12c17_base_eSeries_UR5e_013-mesh" mesh="2526a91bb24bdc844d851a8061563c5c49b4bfe1445f84f9fcebda7b03d12c17_base_eSeries_UR5e_013-mesh" />
      <geom name="tabletop_fixed_joint_lump__base_link_inertia_visual_0" class="robot_unused" type="mesh" contype="0" conaffinity="0" material="material_2526a91bb24bdc844d851a8061563c5c49b4bfe1445f84f9fcebda7b03d12c17_base_eSeries_UR5e_066-mesh" mesh="2526a91bb24bdc844d851a8061563c5c49b4bfe1445f84f9fcebda7b03d12c17_base_eSeries_UR5e_066-mesh" />
      <body name="shoulder_link" gravcomp="1" pos="6.42018e-09 9.51299e-09 0.1625">
        <inertial pos="0 -0.00193 -0.02561" quat="0.73527 -0.287588 0.218944 0.573354" mass="3.761" diaginertia="0.00703079 0.0070003 0.00602478" />
        <joint name="shoulder_pan_joint" class="robot_unused" pos="0 0 0" axis="0 0 1" limited="true" range="-6.28319 6.28319" damping="20" />
        <geom name="shoulder_link_collision" class="robot_unused" quat="0 0 0 1" type="mesh" group="3" mesh="f5ca357fee34c8a14fc8cf256a0c3217c1d95fdfcd83df086610df08316e0b6a_shoulder.stl" />
        <geom name="shoulder_link_visual" class="robot_unused" quat="0 0 0 1" type="mesh" contype="0" conaffinity="0" material="material_2526a91bb24bdc844d851a8061563c5c49b4bfe1445f84f9fcebda7b03d12c17_shoulder_eSeries_UR5e_001-mesh" mesh="2526a91bb24bdc844d851a8061563c5c49b4bfe1445f84f9fcebda7b03d12c17_shoulder_eSeries_UR5e_001-mesh" />
        <geom name="shoulder_link_visual_0" class="robot_unused" quat="0 0 0 1" type="mesh" contype="0" conaffinity="0" material="material_2526a91bb24bdc844d851a8061563c5c49b4bfe1445f84f9fcebda7b03d12c17_shoulder_eSeries_UR5e_067-mesh" mesh="2526a91bb24bdc844d851a8061563c5c49b4bfe1445f84f9fcebda7b03d12c17_shoulder_eSeries_UR5e_067-mesh" />
        <geom name="shoulder_link_visual_1" class="robot_unused" pos="0 0 0" quat="0 0 0 1" type="mesh" contype="0" conaffinity="0" material="material_2526a91bb24bdc844d851a8061563c5c49b4bfe1445f84f9fcebda7b03d12c17_shoulder_eSeries_UR5e_068-mesh" mesh="2526a91bb24bdc844d851a8061563c5c49b4bfe1445f84f9fcebda7b03d12c17_shoulder_eSeries_UR5e_068-mesh" />
        <body name="upper_arm_link" gravcomp="1" pos="-1.94105e-08 2.45398e-08 -8.23834e-08" quat="0.70710678 0.70710678 0 0">
          <inertial pos="-0.2125 0 0.11336" quat="0.500275 0.499641 0.500368 0.499716" mass="8.058" diaginertia="0.333881 0.332472 0.0150588" />
          <joint name="shoulder_lift_joint" class="robot_unused" pos="0 0 0" axis="0 0 1" limited="true" range="-6.28319 6.28319" damping="20" />
          <geom name="upper_arm_link_collision" class="robot_unused" pos="0 0 0.138" quat="0.5 0.5 -0.5 -0.5" type="mesh" group="3" mesh="f5ca357fee34c8a14fc8cf256a0c3217c1d95fdfcd83df086610df08316e0b6a_upperarm.stl" />
          <geom name="upper_arm_link_visual" class="robot_unused" pos="0 0 0.138" quat="0.5 0.5 -0.5 -0.5" type="mesh" contype="0" conaffinity="0" material="material_2526a91bb24bdc844d851a8061563c5c49b4bfe1445f84f9fcebda7b03d12c17_upperarm_merged_0" mesh="2526a91bb24bdc844d851a8061563c5c49b4bfe1445f84f9fcebda7b03d12c17_upperarm_merged_0" />
          <geom name="upper_arm_link_visual_0" class="robot_unused" pos="0 0 0.138" quat="0.5 0.5 -0.5 -0.5" type="mesh" contype="0" conaffinity="0" material="material_2526a91bb24bdc844d851a8061563c5c49b4bfe1445f84f9fcebda7b03d12c17_upperarm_merged_1" mesh="2526a91bb24bdc844d851a8061563c5c49b4bfe1445f84f9fcebda7b03d12c17_upperarm_merged_1" />
          <geom name="upper_arm_link_visual_1" class="robot_unused" pos="0 0 0.138" quat="0.5 0.5 -0.5 -0.5" type="mesh" contype="0" conaffinity="0" material="material_2526a91bb24bdc844d851a8061563c5c49b4bfe1445f84f9fcebda7b03d12c17_upperarm_merged_2" mesh="2526a91bb24bdc844d851a8061563c5c49b4bfe1445f84f9fcebda7b03d12c17_upperarm_merged_2" />
          <geom name="upper_arm_link_visual_2" class="robot_unused" pos="0 0 0.138" quat="0.5 0.5 -0.5 -0.5" type="mesh" contype="0" conaffinity="0" material="material_2526a91bb24bdc844d851a8061563c5c49b4bfe1445f84f9fcebda7b03d12c17_upperarm_eSeries_UR5e_073-mesh" mesh="2526a91bb24bdc844d851a8061563c5c49b4bfe1445f84f9fcebda7b03d12c17_upperarm_eSeries_UR5e_073-mesh" />
          <body name="forearm_link" gravcomp="1" pos="-0.425 -1.6905e-08 7.10882e-08">
            <inertial pos="-0.2422 0 0.0265" quat="0.501301 0.498381 0.510711 0.489375" mass="2.846" diaginertia="0.0787927 0.0785102 0.00397103" />
            <joint name="elbow_joint" class="robot_unused" pos="0 0 0" axis="0 0 1" limited="true" range="-3.14159 3.14159" damping="20" />
            <geom name="forearm_link_collision" class="robot_unused" pos="0 0 0.007" quat="0.5 0.5 -0.5 -0.5" type="mesh" group="3" mesh="f5ca357fee34c8a14fc8cf256a0c3217c1d95fdfcd83df086610df08316e0b6a_forearm.stl" />
            <geom name="forearm_link_visual" class="robot_unused" pos="0 0 0.007" quat="0.5 0.5 -0.5 -0.5" type="mesh" contype="0" conaffinity="0" material="material_2526a91bb24bdc844d851a8061563c5c49b4bfe1445f84f9fcebda7b03d12c17_forearm_merged_0" mesh="2526a91bb24bdc844d851a8061563c5c49b4bfe1445f84f9fcebda7b03d12c17_forearm_merged_0" />
            <geom name="forearm_link_visual_0" class="robot_unused" pos="0 0 0.007" quat="0.5 0.5 -0.5 -0.5" type="mesh" contype="0" conaffinity="0" material="material_2526a91bb24bdc844d851a8061563c5c49b4bfe1445f84f9fcebda7b03d12c17_forearm_merged_1" mesh="2526a91bb24bdc844d851a8061563c5c49b4bfe1445f84f9fcebda7b03d12c17_forearm_merged_1" />
            <geom name="forearm_link_visual_1" class="robot_unused" pos="0 0 0.007" quat="0.5 0.5 -0.5 -0.5" type="mesh" contype="0" conaffinity="0" material="material_2526a91bb24bdc844d851a8061563c5c49b4bfe1445f84f9fcebda7b03d12c17_forearm_eSeries_UR5e_079-mesh" mesh="2526a91bb24bdc844d851a8061563c5c49b4bfe1445f84f9fcebda7b03d12c17_forearm_eSeries_UR5e_079-mesh" />
            <geom name="forearm_link_visual_2" class="robot_unused" pos="0 0 0.007" quat="0.5 0.5 -0.5 -0.5" type="mesh" contype="0" conaffinity="0" material="material_2526a91bb24bdc844d851a8061563c5c49b4bfe1445f84f9fcebda7b03d12c17_forearm_eSeries_UR5e_081-mesh" mesh="2526a91bb24bdc844d851a8061563c5c49b4bfe1445f84f9fcebda7b03d12c17_forearm_eSeries_UR5e_081-mesh" />
            <body name="wrist_1_link" gravcomp="1" pos="-0.3922 3.80072e-08 0.1333">
              <inertial pos="0 -0.01634 -0.0018" quat="0.482884 0.875621 0.0101022 -0.00281842" mass="1.37" diaginertia="0.00165502 0.00142363 0.00119868" />
              <joint name="wrist_1_joint" class="robot_unused" pos="0 0 0" axis="0 0 1" limited="true" range="-6.28319 6.28319" damping="10" />
              <geom name="wrist_1_link_collision" class="robot_unused" pos="0 0 -0.127" quat="0.707107 0.707107 0 0" type="mesh" group="3" mesh="f5ca357fee34c8a14fc8cf256a0c3217c1d95fdfcd83df086610df08316e0b6a_wrist1.stl" />
              <geom name="wrist_1_link_visual" class="robot_unused" pos="0 0 -0.127" quat="0.707107 0.707107 0 0" type="mesh" contype="0" conaffinity="0" material="material_2526a91bb24bdc844d851a8061563c5c49b4bfe1445f84f9fcebda7b03d12c17_wrist1_eSeries_UR5e_043-mesh" mesh="2526a91bb24bdc844d851a8061563c5c49b4bfe1445f84f9fcebda7b03d12c17_wrist1_eSeries_UR5e_043-mesh" />
              <geom name="wrist_1_link_visual_0" class="robot_unused" pos="0 0 -0.127" quat="0.707107 0.707107 0 0" type="mesh" contype="0" conaffinity="0" material="material_2526a91bb24bdc844d851a8061563c5c49b4bfe1445f84f9fcebda7b03d12c17_wrist1_eSeries_UR5e_083-mesh" mesh="2526a91bb24bdc844d851a8061563c5c49b4bfe1445f84f9fcebda7b03d12c17_wrist1_eSeries_UR5e_083-mesh" />
              <geom name="wrist_1_link_visual_1" class="robot_unused" pos="0 0 -0.127" quat="0.707107 0.707107 0 0" type="mesh" contype="0" conaffinity="0" material="material_2526a91bb24bdc844d851a8061563c5c49b4bfe1445f84f9fcebda7b03d12c17_wrist1_eSeries_UR5e_084-mesh" mesh="2526a91bb24bdc844d851a8061563c5c49b4bfe1445f84f9fcebda7b03d12c17_wrist1_eSeries_UR5e_084-mesh" />
              <body name="wrist_2_link" gravcomp="1" pos="4.90372e-08 -0.0997 -8.1574e-09" quat="0.70710678 0.70710678 0 0">
                <inertial pos="0 0.01634 -0.0018" quat="0.759847 0.649632 -0.0119443 0.0216264" mass="1.3" diaginertia="0.00135637 0.00128607 0.00095814" />
                <joint name="wrist_2_joint" class="robot_unused" pos="0 0 0" axis="0 0 1" limited="true" range="-6.28319 6.28319" damping="10" />
                <geom name="wrist_2_link_collision" class="robot_unused" pos="0 0 -0.0997" quat="1 0 0 0" type="mesh" group="3" mesh="f5ca357fee34c8a14fc8cf256a0c3217c1d95fdfcd83df086610df08316e0b6a_wrist2.stl" />
                <geom name="wrist_2_link_visual" class="robot_unused" pos="0 0 -0.0997" quat="1 0 0 0" type="mesh" contype="0" conaffinity="0" material="material_2526a91bb24bdc844d851a8061563c5c49b4bfe1445f84f9fcebda7b03d12c17_wrist2_eSeries_UR5e_049-mesh" mesh="2526a91bb24bdc844d851a8061563c5c49b4bfe1445f84f9fcebda7b03d12c17_wrist2_eSeries_UR5e_049-mesh" />
                <geom name="wrist_2_link_visual_0" class="robot_unused" pos="0 0 -0.0997" quat="1 0 0 0" type="mesh" contype="0" conaffinity="0" material="material_2526a91bb24bdc844d851a8061563c5c49b4bfe1445f84f9fcebda7b03d12c17_wrist2_eSeries_UR5e_085-mesh" mesh="2526a91bb24bdc844d851a8061563c5c49b4bfe1445f84f9fcebda7b03d12c17_wrist2_eSeries_UR5e_085-mesh" />
                <geom name="wrist_2_link_visual_1" class="robot_unused" pos="0 0 -0.0997" quat="1 0 0 0" type="mesh" contype="0" conaffinity="0" material="material_2526a91bb24bdc844d851a8061563c5c49b4bfe1445f84f9fcebda7b03d12c17_wrist2_eSeries_UR5e_086-mesh" mesh="2526a91bb24bdc844d851a8061563c5c49b4bfe1445f84f9fcebda7b03d12c17_wrist2_eSeries_UR5e_086-mesh" />
                <body name="wrist_3_link" gravcomp="1" pos="4.08407e-08 0.0996001 3.92768e-08" quat="0.70710678 -0.70710678 0 0">
                  <inertial pos="0 -0.000295454 -0.000755283" quat="0.716686 -0.00126424 0.00131506 0.697394" mass="0.729" diaginertia="0.00200498 0.00200276 0.000606738" />
                  <joint name="wrist_3_joint" class="robot_unused" pos="0 0 0" axis="0 0 1" limited="true" range="-6.28319 6.28319" damping="10" />
                  <geom name="wrist_3_link_collision" class="robot_unused" pos="0 0 -0.0989" quat="0.707107 0.707107 0 0" type="mesh" group="3" mesh="f5ca357fee34c8a14fc8cf256a0c3217c1d95fdfcd83df086610df08316e0b6a_wrist3.stl" />
                  <geom name="wrist_3_link_fixed_joint_lump__cam_mount_collider_cylinder_collision_1" class="robot_unused" size="0.06 0.005" pos="0 0 -0.005" type="cylinder" group="3" />
                  <geom name="wrist_3_link_fixed_joint_lump__cam_mount_collider_cylinder.001_collision_2" class="robot_unused" size="0.030383 0.0126375" pos="0 0 -0.013862" type="cylinder" group="3" />
                  <geom name="wrist_3_link_fixed_joint_lump__cam_mount003_collider_box_collision_3" class="robot_unused" size="0.0278375 0.018449 0.0022" pos="0.000252 -0.068974 -0.0072" quat="0.707107 0 0 -0.707107" type="box" group="3" />
                  <geom name="wrist_3_link_fixed_joint_lump__cam_mount003_collider_box.001_collision_4" class="robot_unused" size="0.017628 0.021625 0.00429" pos="0.000189 -0.100267 -0.022574" quat="0.560986 0.430459 0.430459 -0.560985" type="box" group="3" />
                  <geom name="wrist_3_link_fixed_joint_lump__cam_mount003_collider_box.002_collision_5" class="robot_unused" size="0.0297835 0.018449 0.005221" pos="0.000252 -0.076575 -0.019058" quat="0.686843 0.168069 0.168069 -0.686842" type="box" group="3" />
                  <geom name="wrist_3_link_fixed_joint_lump__cam_mount003_collider_box.003_collision_6" class="robot_unused" size="0.0278375 0.018449 0.0022" pos="0.059859 -0.034268 -0.0072" quat="0.965926 0 0 -0.258819" type="box" group="3" />
                  <geom name="wrist_3_link_fixed_joint_lump__cam_mount003_collider_box.004_collision_7" class="robot_unused" size="0.017628 0.021625 0.00429" pos="0.086928 -0.04997 -0.022574" quat="0.76632 0.157559 0.588018 -0.205335" type="box" group="3" />
                  <geom name="wrist_3_link_fixed_joint_lump__cam_mount003_collider_box.005_collision_8" class="robot_unused" size="0.0301105 0.018449 0.005221" pos="0.06619 -0.037924 -0.018907" quat="0.938244 0.0615176 0.229587 -0.251402" type="box" group="3" />
                  <geom name="wrist_3_link_fixed_joint_lump__cam_mount003_collider_box.006_collision_9" class="robot_unused" size="0.0278375 0.018449 0.0022" pos="-0.059607 -0.034705 -0.0072" quat="0.258819 0 0 -0.965926" type="box" group="3" />
                  <geom name="wrist_3_link_fixed_joint_lump__cam_mount003_collider_box.007_collision_10" class="robot_unused" size="0.017628 0.021625 0.00429" pos="-0.08674 -0.050297 -0.022574" quat="0.205335 0.588018 0.157559 -0.76632" type="box" group="3" />
                  <geom name="wrist_3_link_fixed_joint_lump__cam_mount003_collider_box.008_collision_11" class="robot_unused" size="0.02985 0.018449 0.005221" pos="-0.066139 -0.038476 -0.019027" quat="0.251402 0.229587 0.0615176 -0.938244" type="box" group="3" />
                  <geom name="wrist_3_link_fixed_joint_lump__body_collider_box_collision_12" class="robot_unused" size="0.02415 0.0145 0.0145" pos="-1.29182e-09 -0.121046 -0.027474" quat="0.560986 0.430459 -0.430459 0.560986" type="box" group="3" />
                  <geom name="wrist_3_link_fixed_joint_lump__lens_collider_cylinder_collision_13" class="robot_unused" size="0.015631 0.02163" pos="-1.44918e-10 -0.109197 0.0167461" quat="0.701057 -0.0922975 0.0922975 0.701057" type="cylinder" group="3" />
                  <geom name="wrist_3_link_fixed_joint_lump__axia80_m20_collider_cylinder_collision_14" class="robot_unused" size="0.041519 0.0126995" pos="0 -4e-06 0.012699" quat="1.73205e-07 -1 0 0" type="cylinder" group="3" />
                  <geom name="wrist_3_link_fixed_joint_lump__axia80_m20001_collider_cylinder_collision_15" class="robot_unused" size="0.006027 0.0083585" pos="0 0.041828 0.018432" quat="0.707107 -0.707107 0 0" type="cylinder" group="3" />
                  <geom name="wrist_3_link_fixed_joint_lump__body_collider_box_collision_16" class="robot_unused" size="0.02415 0.0145 0.0145" pos="-0.104818 -0.060516 -0.027472" quat="0.766321 0.157559 -0.588018 0.205335" type="box" group="3" />
                  <geom name="wrist_3_link_fixed_joint_lump__lens_collider_cylinder_collision_17" class="robot_unused" size="0.015631 0.02163" pos="-0.0945566 -0.0545916 0.0167481" quat="0.957662 -0.0337832 0.126081 0.256605" type="cylinder" group="3" />
                  <geom name="wrist_3_link_fixed_joint_lump__body_collider_box_collision_18" class="robot_unused" size="0.02415 0.0145 0.0145" pos="0.104818 -0.060516 -0.027472" quat="0.205335 0.588018 -0.157559 0.766321" type="box" group="3" />
                  <geom name="wrist_3_link_fixed_joint_lump__lens_collider_cylinder_collision_19" class="robot_unused" size="0.015631 0.02163" pos="0.0945566 -0.0545916 0.0167481" quat="0.256605 -0.126081 0.0337832 0.957662" type="cylinder" group="3" />
                  <geom name="wrist_3_link_visual" class="robot_unused" pos="0 0 -0.0989" quat="0.707107 0.707107 0 0" type="mesh" contype="0" conaffinity="0" material="material_2526a91bb24bdc844d851a8061563c5c49b4bfe1445f84f9fcebda7b03d12c17_wrist3_eSeries_UR5e_058-mesh" mesh="2526a91bb24bdc844d851a8061563c5c49b4bfe1445f84f9fcebda7b03d12c17_wrist3_eSeries_UR5e_058-mesh" />
                  <geom name="wrist_3_link_fixed_joint_lump__cam_mount_visual_visual_1" class="robot_unused" pos="0 0 -0.0265" quat="1 0 0 0" type="mesh" contype="0" conaffinity="0" material="material_9883659ad3e180e4613cb31e888868fb6599c2975f7d6bb9ef140bf2782bae64_cam_mount_visual_Cam_Mount.001" mesh="9883659ad3e180e4613cb31e888868fb6599c2975f7d6bb9ef140bf2782bae64_cam_mount_visual_Cam_Mount.001" />
                  <geom name="wrist_3_link_fixed_joint_lump__cam_mount_visual_visual_1_0" class="robot_unused" pos="0 0 -0.0265" quat="1 0 0 0" type="mesh" contype="0" conaffinity="0" material="material_9883659ad3e180e4613cb31e888868fb6599c2975f7d6bb9ef140bf2782bae64_cam_mount_visual_Cam_Mount.001_1" mesh="9883659ad3e180e4613cb31e888868fb6599c2975f7d6bb9ef140bf2782bae64_cam_mount_visual_Cam_Mount.001_1" />
                  <geom name="wrist_3_link_fixed_joint_lump__basler_cam_visual_visual_2" class="robot_unused" pos="0 -0.1077 -0.03369" quat="0.991445 -0.130528 1.82721e-06 -2.87705e-07" type="mesh" contype="0" conaffinity="0" material="material_479655a6843b0953e26a94d9816615add694660aa31c6c93a9863e851478702a_basler_cam_visual_59871rev000.001" mesh="479655a6843b0953e26a94d9816615add694660aa31c6c93a9863e851478702a_basler_cam_visual_59871rev000.001" />
                  <geom name="wrist_3_link_fixed_joint_lump__basler_cam_visual_visual_2_0" class="robot_unused" pos="0 -0.1077 -0.03369" quat="0.991445 -0.130528 1.82721e-06 -2.87705e-07" type="mesh" contype="0" conaffinity="0" material="material_479655a6843b0953e26a94d9816615add694660aa31c6c93a9863e851478702a_basler_cam_visual_59871rev000.001_1" mesh="479655a6843b0953e26a94d9816615add694660aa31c6c93a9863e851478702a_basler_cam_visual_59871rev000.001_1" />
                  <geom name="wrist_3_link_fixed_joint_lump__basler_cam_visual_visual_2_1" class="robot_unused" pos="0 -0.1077 -0.03369" quat="0.991445 -0.130528 1.82721e-06 -2.87705e-07" type="mesh" contype="0" conaffinity="0" material="material_479655a6843b0953e26a94d9816615add694660aa31c6c93a9863e851478702a_basler_cam_visual_59871rev000.001_2" mesh="479655a6843b0953e26a94d9816615add694660aa31c6c93a9863e851478702a_basler_cam_visual_59871rev000.001_2" />
                  <geom name="wrist_3_link_fixed_joint_lump__basler_cam_visual_visual_2_2" class="robot_unused" pos="0 -0.1077 -0.03369" quat="0.991445 -0.130528 1.82721e-06 -2.87705e-07" type="mesh" contype="0" conaffinity="0" material="material_479655a6843b0953e26a94d9816615add694660aa31c6c93a9863e851478702a_basler_cam_visual_59871rev000.001_3" mesh="479655a6843b0953e26a94d9816615add694660aa31c6c93a9863e851478702a_basler_cam_visual_59871rev000.001_3" />
                  <geom name="wrist_3_link_fixed_joint_lump__basler_cam_visual_visual_2_3" class="robot_unused" pos="0 -0.1077 -0.03369" quat="0.991445 -0.130528 1.82721e-06 -2.87705e-07" type="mesh" contype="0" conaffinity="0" material="material_479655a6843b0953e26a94d9816615add694660aa31c6c93a9863e851478702a_basler_cam_visual_59871rev000.001_4" mesh="479655a6843b0953e26a94d9816615add694660aa31c6c93a9863e851478702a_basler_cam_visual_59871rev000.001_4" />
                  <geom name="wrist_3_link_fixed_joint_lump__axia_ft_sensor_visual_visual_3" class="robot_unused" type="mesh" contype="0" conaffinity="0" material="material_a0d54315167580a143651a5a9d7963d83b0b7f25767ad4d48d4d3230ded1362f_axia_ft_sensor_visual_Axia80_M20.001" mesh="a0d54315167580a143651a5a9d7963d83b0b7f25767ad4d48d4d3230ded1362f_axia_ft_sensor_visual_Axia80_M20.001" />
                  <geom name="wrist_3_link_fixed_joint_lump__axia_ft_sensor_visual_visual_3_0" class="robot_unused" type="mesh" contype="0" conaffinity="0" material="material_a0d54315167580a143651a5a9d7963d83b0b7f25767ad4d48d4d3230ded1362f_axia_ft_sensor_visual_Axia80_M20.001_1" mesh="a0d54315167580a143651a5a9d7963d83b0b7f25767ad4d48d4d3230ded1362f_axia_ft_sensor_visual_Axia80_M20.001_1" />
                  <geom name="wrist_3_link_fixed_joint_lump__axia_ft_sensor_visual_visual_3_1" class="robot_unused" type="mesh" contype="0" conaffinity="0" material="material_a0d54315167580a143651a5a9d7963d83b0b7f25767ad4d48d4d3230ded1362f_axia_ft_sensor_visual_Axia80_M20.001_2" mesh="a0d54315167580a143651a5a9d7963d83b0b7f25767ad4d48d4d3230ded1362f_axia_ft_sensor_visual_Axia80_M20.001_2" />
                  <geom name="wrist_3_link_fixed_joint_lump__axia_ft_sensor_visual_visual_3_2" class="robot_unused" type="mesh" contype="0" conaffinity="0" material="material_a0d54315167580a143651a5a9d7963d83b0b7f25767ad4d48d4d3230ded1362f_axia_ft_sensor_visual_Axia80_M20.001_3" mesh="a0d54315167580a143651a5a9d7963d83b0b7f25767ad4d48d4d3230ded1362f_axia_ft_sensor_visual_Axia80_M20.001_3" />
                  <geom name="wrist_3_link_fixed_joint_lump__axia_ft_sensor_visual_visual_3_3" class="robot_unused" type="mesh" contype="0" conaffinity="0" material="material_a0d54315167580a143651a5a9d7963d83b0b7f25767ad4d48d4d3230ded1362f_axia_ft_sensor_visual_Axia80_M20.001_4" mesh="a0d54315167580a143651a5a9d7963d83b0b7f25767ad4d48d4d3230ded1362f_axia_ft_sensor_visual_Axia80_M20.001_4" />
                  <geom name="wrist_3_link_fixed_joint_lump__basler_cam_visual_visual_4" class="robot_unused" pos="-0.09326 -0.053843 -0.033688" quat="0.858616 -0.11304 0.0652657 -0.495722" type="mesh" contype="0" conaffinity="0" material="material_479655a6843b0953e26a94d9816615add694660aa31c6c93a9863e851478702a_basler_cam_visual_59871rev000.001" mesh="479655a6843b0953e26a94d9816615add694660aa31c6c93a9863e851478702a_basler_cam_visual_59871rev000.001" />
                  <geom name="wrist_3_link_fixed_joint_lump__basler_cam_visual_visual_4_0" class="robot_unused" pos="-0.09326 -0.053843 -0.033688" quat="0.858616 -0.11304 0.0652657 -0.495722" type="mesh" contype="0" conaffinity="0" material="material_479655a6843b0953e26a94d9816615add694660aa31c6c93a9863e851478702a_basler_cam_visual_59871rev000.001_1" mesh="479655a6843b0953e26a94d9816615add694660aa31c6c93a9863e851478702a_basler_cam_visual_59871rev000.001_1" />
                  <geom name="wrist_3_link_fixed_joint_lump__basler_cam_visual_visual_4_1" class="robot_unused" pos="-0.09326 -0.053843 -0.033688" quat="0.858616 -0.11304 0.0652657 -0.495722" type="mesh" contype="0" conaffinity="0" material="material_479655a6843b0953e26a94d9816615add694660aa31c6c93a9863e851478702a_basler_cam_visual_59871rev000.001_2" mesh="479655a6843b0953e26a94d9816615add694660aa31c6c93a9863e851478702a_basler_cam_visual_59871rev000.001_2" />
                  <geom name="wrist_3_link_fixed_joint_lump__basler_cam_visual_visual_4_2" class="robot_unused" pos="-0.09326 -0.053843 -0.033688" quat="0.858616 -0.11304 0.0652657 -0.495722" type="mesh" contype="0" conaffinity="0" material="material_479655a6843b0953e26a94d9816615add694660aa31c6c93a9863e851478702a_basler_cam_visual_59871rev000.001_3" mesh="479655a6843b0953e26a94d9816615add694660aa31c6c93a9863e851478702a_basler_cam_visual_59871rev000.001_3" />
                  <geom name="wrist_3_link_fixed_joint_lump__basler_cam_visual_visual_4_3" class="robot_unused" pos="-0.09326 -0.053843 -0.033688" quat="0.858616 -0.11304 0.0652657 -0.495722" type="mesh" contype="0" conaffinity="0" material="material_479655a6843b0953e26a94d9816615add694660aa31c6c93a9863e851478702a_basler_cam_visual_59871rev000.001_4" mesh="479655a6843b0953e26a94d9816615add694660aa31c6c93a9863e851478702a_basler_cam_visual_59871rev000.001_4" />
                  <geom name="wrist_3_link_fixed_joint_lump__basler_cam_visual_visual_5" class="robot_unused" pos="0.09326 -0.053843 -0.033688" quat="0.858616 -0.113042 -0.0652626 0.495722" type="mesh" contype="0" conaffinity="0" material="material_479655a6843b0953e26a94d9816615add694660aa31c6c93a9863e851478702a_basler_cam_visual_59871rev000.001" mesh="479655a6843b0953e26a94d9816615add694660aa31c6c93a9863e851478702a_basler_cam_visual_59871rev000.001" />
                  <geom name="wrist_3_link_fixed_joint_lump__basler_cam_visual_visual_5_0" class="robot_unused" pos="0.09326 -0.053843 -0.033688" quat="0.858616 -0.113042 -0.0652626 0.495722" type="mesh" contype="0" conaffinity="0" material="material_479655a6843b0953e26a94d9816615add694660aa31c6c93a9863e851478702a_basler_cam_visual_59871rev000.001_1" mesh="479655a6843b0953e26a94d9816615add694660aa31c6c93a9863e851478702a_basler_cam_visual_59871rev000.001_1" />
                  <geom name="wrist_3_link_fixed_joint_lump__basler_cam_visual_visual_5_1" class="robot_unused" pos="0.09326 -0.053843 -0.033688" quat="0.858616 -0.113042 -0.0652626 0.495722" type="mesh" contype="0" conaffinity="0" material="material_479655a6843b0953e26a94d9816615add694660aa31c6c93a9863e851478702a_basler_cam_visual_59871rev000.001_2" mesh="479655a6843b0953e26a94d9816615add694660aa31c6c93a9863e851478702a_basler_cam_visual_59871rev000.001_2" />
                  <geom name="wrist_3_link_fixed_joint_lump__basler_cam_visual_visual_5_2" class="robot_unused" pos="0.09326 -0.053843 -0.033688" quat="0.858616 -0.113042 -0.0652626 0.495722" type="mesh" contype="0" conaffinity="0" material="material_479655a6843b0953e26a94d9816615add694660aa31c6c93a9863e851478702a_basler_cam_visual_59871rev000.001_3" mesh="479655a6843b0953e26a94d9816615add694660aa31c6c93a9863e851478702a_basler_cam_visual_59871rev000.001_3" />
                  <geom name="wrist_3_link_fixed_joint_lump__basler_cam_visual_visual_5_3" class="robot_unused" pos="0.09326 -0.053843 -0.033688" quat="0.858616 -0.113042 -0.0652626 0.495722" type="mesh" contype="0" conaffinity="0" material="material_479655a6843b0953e26a94d9816615add694660aa31c6c93a9863e851478702a_basler_cam_visual_59871rev000.001_4" mesh="479655a6843b0953e26a94d9816615add694660aa31c6c93a9863e851478702a_basler_cam_visual_59871rev000.001_4" />
                  <body name="center_camera/sensor_link" gravcomp="1" pos="2.30133e-08 -0.116079 -0.00893793" quat="0.560986 0.430459 -0.430459 0.560986">
                    <inertial pos="0 0 0" mass="0.001" diaginertia="1e-06 1e-06 1e-06" />
                    <camera name="center_camera" class="robot_unused" pos="0 0 0" quat="0.5 0.5 -0.5 -0.5" fovy="44.982" resolution="1152 1024" />
                    <body name="center_camera/optical" gravcomp="1" pos="0 0 0" quat="0.499998 -0.5 0.500002 -0.5">
                      <inertial pos="0 0 0" mass="0.001" diaginertia="1e-06 1e-06 1e-06" />
                    </body>
                  </body>
                  <body name="ati/tool_link" gravcomp="1" pos="-2.0285e-09 -1.89459e-09 0.0245" quat="1 -5.16864e-08 2.1037e-09 -1.25278e-07">
                    <inertial pos="0 0 0" mass="1.001" diaginertia="0.100001 0.100001 0.100001" />
                    <geom name="ati/tool_link_fixed_joint_lump__body_collider_cylinder_collision" class="robot_unused" size="0.038 0.05655" pos="0 0 0.06855" quat="1.22475e-07 -0.707107 -0.707107 1.22474e-07" type="cylinder" group="3" />
                    <geom name="ati/tool_link_fixed_joint_lump__cylinder003_collider_cylinder_collision_1" class="robot_unused" size="0.043 0.006" pos="0 0 0.006" type="cylinder" group="3" />
                    <geom name="ati/tool_link_fixed_joint_lump__hande_base_visual_visual" class="robot_unused" type="mesh" contype="0" conaffinity="0" material="material_354908445af88fcf1366e0e4d2bd23726354cdb419dd151b3c01461be6e77331_hande_base_visual_Cylinder.004" mesh="354908445af88fcf1366e0e4d2bd23726354cdb419dd151b3c01461be6e77331_hande_base_visual_Cylinder.004" />
                    <geom name="ati/tool_link_fixed_joint_lump__hande_base_visual_visual_0" class="robot_unused" type="mesh" contype="0" conaffinity="0" material="material_354908445af88fcf1366e0e4d2bd23726354cdb419dd151b3c01461be6e77331_hande_base_visual_Cylinder.004_1" mesh="354908445af88fcf1366e0e4d2bd23726354cdb419dd151b3c01461be6e77331_hande_base_visual_Cylinder.004_1" />
                    <geom name="ati/tool_link_fixed_joint_lump__hande_base_visual_visual_1" class="robot_unused" type="mesh" contype="0" conaffinity="0" material="material_354908445af88fcf1366e0e4d2bd23726354cdb419dd151b3c01461be6e77331_hande_base_visual_Cylinder.004_2" mesh="354908445af88fcf1366e0e4d2bd23726354cdb419dd151b3c01461be6e77331_hande_base_visual_Cylinder.004_2" />
                    <geom name="ati/tool_link_fixed_joint_lump__hande_base_visual_visual_2" class="robot_unused" type="mesh" contype="0" conaffinity="0" material="material_354908445af88fcf1366e0e4d2bd23726354cdb419dd151b3c01461be6e77331_hande_base_visual_Cylinder.004_3" mesh="354908445af88fcf1366e0e4d2bd23726354cdb419dd151b3c01461be6e77331_hande_base_visual_Cylinder.004_3" />
                    <geom name="ati/tool_link_fixed_joint_lump__hande_base_visual_visual_3" class="robot_unused" type="mesh" contype="0" conaffinity="0" material="material_354908445af88fcf1366e0e4d2bd23726354cdb419dd151b3c01461be6e77331_hande_base_visual_Cylinder.004_4" mesh="354908445af88fcf1366e0e4d2bd23726354cdb419dd151b3c01461be6e77331_hande_base_visual_Cylinder.004_4" />
                    <geom name="ati/tool_link_fixed_joint_lump__hande_base_visual_visual_4" class="robot_unused" type="mesh" contype="0" conaffinity="0" material="material_354908445af88fcf1366e0e4d2bd23726354cdb419dd151b3c01461be6e77331_hande_base_visual_Cylinder.004_5" mesh="354908445af88fcf1366e0e4d2bd23726354cdb419dd151b3c01461be6e77331_hande_base_visual_Cylinder.004_5" />
                    <geom name="ati/tool_link_fixed_joint_lump__hande_base_visual_visual_5" class="robot_unused" type="mesh" contype="0" conaffinity="0" material="material_354908445af88fcf1366e0e4d2bd23726354cdb419dd151b3c01461be6e77331_hande_base_visual_Cylinder.004_6" mesh="354908445af88fcf1366e0e4d2bd23726354cdb419dd151b3c01461be6e77331_hande_base_visual_Cylinder.004_6" />
                    <site name="AtiForceTorqueSensor" class="robot_unused" pos="0 0 0" />
                    <site name="gripper_tcp" pos="0 0 0.172" />
                    
                    <body name="lc_plug_link" gravcomp="1" pos="-0.000711 0.001759 0.168213" quat="0.577301 0.816105 -0.021418 -0.015395">
                      <inertial pos="0 0.0197 0" quat="0 0.707107 0 0.707107" mass="0.01" diaginertia="1.06153e-07 9.96094e-08 8.49658e-09" />
                      <geom name="cylinder001_collider_cylinder.001" size="0.000625 0.001502" pos="0.003125 0.0197 0" quat="0.707107 0.707107 0 0" type="cylinder" group="3" />
                      <geom name="cylinder_collider_cylinder.001" size="0.000625 0.001502" pos="-0.003125 0.0197 0" quat="0.707107 0.707107 0 0" type="cylinder" group="3" />
                      <geom name="lc_plug_visual" type="mesh" contype="0" conaffinity="0" material="material_49bcaba7dbdb7d3142691518ed2731a8b4b7bed5e5dd55a10defd679994a8fb5_lc_plug_visual_merged_0" mesh="49bcaba7dbdb7d3142691518ed2731a8b4b7bed5e5dd55a10defd679994a8fb5_lc_plug_visual_merged_0" />
                      <body name="sfp_module_link" gravcomp="1" pos="0 0.0384 0" quat="0 1 0 0">
                        <inertial pos="0.00024115 0.00702224 0.000553372" quat="0.510037 0.497012 -0.483415 0.50907" mass="0.02" diaginertia="3.07513e-06 2.81054e-06 5.69919e-07" />
                        <geom name="port_collider_box.008" size="0.00071 0.000503 0.0064415" pos="-0.00571 0.018813 -0.003546" quat="0.707107 0.707107 0 0" type="box" group="3" />
                        <geom name="port_collider_box.009" size="0.00071 0.000503 0.0064415" pos="0.00571 0.018813 -0.003546" quat="0.707107 0.707107 0 0" type="box" group="3" />
                        <geom name="body_collider_box" size="0.006875 0.02365 0.0003945" pos="0 0.001 0.00383" type="box" group="3" />
                        <geom name="body_collider_box.001" size="0.006875 0.02365 8.9e-05" pos="0 0.001 -0.004138" type="box" group="3" />
                        <geom name="body_collider_box.002" size="0.000287 0.02365 0.004225" pos="-0.006588 0.001 0" type="box" group="3" />
                        <geom name="body_collider_box.003" size="0.0004055 0.02365 0.004225" pos="0.00647 0.001 0" type="box" group="3" />
                        <geom name="port_collider_box.010" size="0.00642 0.0038815 0.0058645" pos="0 0.01229 0.000119" quat="0.707107 0.707107 0 0" type="box" group="3" />
                        <geom name="port_collider_box002_collider_box" size="0.00642 0.0002045 0.0008005" pos="0 0.024453 -0.004254" quat="0.707107 0.707107 0 0" type="box" group="3" />
                        <geom name="port_collider_box.011" size="0.00125 0.000503 0.0064415" pos="0 0.018813 -0.003546" quat="0.707107 0.707107 0 0" type="box" group="3" />
                        <geom name="sfp_module_visual" type="mesh" contype="0" conaffinity="0" material="material_4e46908e7d54f1b9f4b24d75a3e64fbc26cc8ba53b13e641c435298d0fee7478_sfp_module_visual_Body.005" mesh="4e46908e7d54f1b9f4b24d75a3e64fbc26cc8ba53b13e641c435298d0fee7478_sfp_module_visual_Body.005" />
                        <geom name="sfp_module_visual_0" type="mesh" contype="0" conaffinity="0" material="material_4e46908e7d54f1b9f4b24d75a3e64fbc26cc8ba53b13e641c435298d0fee7478_sfp_module_visual_Body.005_1" mesh="4e46908e7d54f1b9f4b24d75a3e64fbc26cc8ba53b13e641c435298d0fee7478_sfp_module_visual_Body.005_1" />
                        <body name="sfp_tip_link" gravcomp="1" pos="0 -0.02365 0" quat="0.707105 0.707108 0 0">
                          <inertial pos="0 0 0" mass="0.001" diaginertia="1e-06 1e-06 1e-06" />
                          <geom name="contact_collision" size="0.006875 0.0021125 0.0005" pos="0 0.0021125 -0.0005" type="box" group="3" />
                          <geom name="non_contact_collision" size="0.006875 0.0021125 0.0005" pos="0 -0.0021125 -0.0005" type="box" group="3" />
                        </body>
                      </body>
                    <body name="cable_end_0" childclass="cable_default" pos="0 0 0" quat="1 0 0 0">
      <joint name="cable_plug_attach" type="ball" damping="2.0" armature="0.1" /><inertial pos="0 0 0" mass="0.01" diaginertia="1e-4 1e-4 1e-4" />
      <geom name="base_vis" class="world_default" size="0.002" contype="0" conaffinity="0" />
      <plugin instance="composite" />
      <body name="cable_connection_0" pos="-2.48032e-08 2.17152e-08 -1.45797e-07" quat="0.922729 -0.0944968 -0.331446 0.172583">
        <inertial pos="0 0 0" mass="0.01" diaginertia="1e-6 1e-6 1e-6" />
        <joint name="joint_connection_end_0" class="cable_default" pos="0 0 0" type="ball" damping="5.0" armature="0.1" />
        <geom name="visual_0_0" class="world_default" size="0.001 0.00180278" pos="-0.00180278 0.002 0" quat="0.676768 0.204909 0.676764 -0.204908" type="cylinder" contype="0" conaffinity="0" />
        <geom name="visual_1_0" class="world_default" size="0.001 0.00180278" pos="-0.00180278 -0.002 0" quat="0.676768 -0.204909 0.676764 0.204908" type="cylinder" contype="0" conaffinity="0" />
        <plugin instance="composite" />
        <body name="link_1" pos="0.00170632 -0.00556858 -0.0232827" quat="-0.0670116 -0.276934 -0.95308 0.102252">
          <inertial pos="0 0 0" mass="0.0025" diaginertia="1e-6 1e-6 1e-6" />
          <joint name="joint_end_0" pos="0 0 -0.024" type="ball" />
          <geom name="link_1_collision" size="0.002 0.018" pos="0 0 0.006" type="cylinder" group="3" />
          <geom name="sphere_1_collision" size="0.002" pos="0 0 0.024" group="3" />
          <geom name="link_1_vis" size="0.002 0.024" type="cylinder" contype="0" conaffinity="0" />
          <geom name="sphere_1_vis" size="0.002" pos="0 0 0.024" contype="0" conaffinity="0" />
          <plugin instance="composite" />
          <body name="link_2" pos="0.0064563 -0.00759576 0.045832" quat="0.976992 0.159419 0.140563 -0.0177353">
            <inertial pos="0 0 0" mass="0.0025" diaginertia="1e-6 1e-6 1e-6" />
            <joint name="joint_1" pos="0 0 -0.024" type="ball" />
            <geom name="link_2_collision" size="0.002 0.024" type="cylinder" group="3" />
            <geom name="sphere_2_collision" size="0.002" pos="0 0 0.024" group="3" />
            <geom name="link_2_vis" size="0.002 0.024" type="cylinder" contype="0" conaffinity="0" />
            <geom name="sphere_2_vis" size="0.002" pos="0 0 0.024" contype="0" conaffinity="0" />
            <plugin instance="composite" />
            <body name="link_3" pos="0.000666041 -0.00668751 0.0470402" quat="0.98975 0.140425 0.0168223 -0.0198334">
              <inertial pos="0 0 0" mass="0.0025" diaginertia="1e-6 1e-6 1e-6" />
              <joint name="joint_2" pos="0 0 -0.024" type="ball" />
              <geom name="link_3_collision" size="0.002 0.024" type="cylinder" group="3" />
              <geom name="sphere_3_collision" size="0.002" pos="0 0 0.024" group="3" />
              <geom name="link_3_vis" size="0.002 0.024" type="cylinder" contype="0" conaffinity="0" />
              <geom name="sphere_3_vis" size="0.002" pos="0 0 0.024" contype="0" conaffinity="0" />
              <plugin instance="composite" />
              <body name="link_4" pos="-0.00201756 -0.0046759 0.0474536" quat="0.994004 0.0989623 -0.0399132 -0.0238771">
                <inertial pos="0 0 0" mass="0.0025" diaginertia="1e-6 1e-6 1e-6" />
                <joint name="joint_3" pos="0 0 -0.024" type="ball" />
                <geom name="link_4_collision" size="0.002 0.024" type="cylinder" group="3" />
                <geom name="sphere_4_collision" size="0.002" pos="0 0 0.024" group="3" />
                <geom name="link_4_vis" size="0.002 0.024" type="cylinder" contype="0" conaffinity="0" />
                <geom name="sphere_4_vis" size="0.002" pos="0 0 0.024" contype="0" conaffinity="0" />
                <plugin instance="composite" />
                <body name="link_5" pos="-0.00359934 -0.0031378 0.0475207" quat="0.994211 0.0686286 -0.0727025 -0.0393501">
                  <inertial pos="0 0 0" mass="0.0025" diaginertia="1e-6 1e-6 1e-6" />
                  <joint name="joint_4" pos="0 0 -0.024" type="ball" />
                  <geom name="link_5_collision" size="0.002 0.024" type="cylinder" group="3" />
                  <geom name="sphere_5_collision" size="0.002" pos="0 0 0.024" group="3" />
                  <geom name="link_5_vis" size="0.002 0.024" type="cylinder" contype="0" conaffinity="0" />
                  <geom name="sphere_5_vis" size="0.002" pos="0 0 0.024" contype="0" conaffinity="0" />
                  <plugin instance="composite" />
                  <body name="link_6" pos="-0.00400601 -0.00179596 0.0475953" quat="0.993829 0.0427394 -0.0813241 -0.0621514">
                    <inertial pos="0 0 0" mass="0.0025" diaginertia="1e-6 1e-6 1e-6" />
                    <joint name="joint_5" pos="0 0 -0.024" type="ball" />
                    <geom name="link_6_collision" size="0.002 0.024" type="cylinder" group="3" />
                    <geom name="sphere_6_collision" size="0.002" pos="0 0 0.024" group="3" />
                    <geom name="link_6_vis" size="0.002 0.024" type="cylinder" contype="0" conaffinity="0" />
                    <geom name="sphere_6_vis" size="0.002" pos="0 0 0.024" contype="0" conaffinity="0" />
                    <plugin instance="composite" />
                    <body name="link_7" pos="-0.00359567 -0.000736965 0.0477182" quat="0.993406 0.0217587 -0.0735419 -0.0852205">
                      <inertial pos="0 0 0" mass="0.0025" diaginertia="1e-6 1e-6 1e-6" />
                      <joint name="joint_6" pos="0 0 -0.024" type="ball" />
                      <geom name="link_7_collision" size="0.002 0.024" type="cylinder" group="3" />
                      <geom name="sphere_7_collision" size="0.002" pos="0 0 0.024" group="3" />
                      <geom name="link_7_vis" size="0.002 0.024" type="cylinder" contype="0" conaffinity="0" />
                      <geom name="sphere_7_vis" size="0.002" pos="0 0 0.024" contype="0" conaffinity="0" />
                      <plugin instance="composite" />
                      <body name="link_8" pos="-0.00255335 0.000119986 0.0478642" quat="0.993512 0.00286058 -0.0532556 -0.100445">
                        <inertial pos="0 0 0" mass="0.0025" diaginertia="1e-6 1e-6 1e-6" />
                        <joint name="joint_7" pos="0 0 -0.024" type="ball" />
                        <geom name="link_8_collision" size="0.002 0.024" type="cylinder" group="3" />
                        <geom name="sphere_8_collision" size="0.002" pos="0 0 0.024" group="3" />
                        <geom name="link_8_vis" size="0.002 0.024" type="cylinder" contype="0" conaffinity="0" />
                        <geom name="sphere_8_vis" size="0.002" pos="0 0 0.024" contype="0" conaffinity="0" />
                        <plugin instance="composite" />
                        <body name="link_9" pos="-0.00133737 0.000859059 0.0479485" quat="0.994153 -0.0149483 -0.0295699 -0.102776">
                          <inertial pos="0 0 0" mass="0.0025" diaginertia="1e-6 1e-6 1e-6" />
                          <joint name="joint_8" pos="0 0 -0.024" type="ball" />
                          <geom name="link_9_collision" size="0.002 0.024" type="cylinder" group="3" />
                          <geom name="sphere_9_collision" size="0.002" pos="0 0 0.024" group="3" />
                          <geom name="link_9_vis" size="0.002 0.024" type="cylinder" contype="0" conaffinity="0" />
                          <geom name="sphere_9_vis" size="0.002" pos="0 0 0.024" contype="0" conaffinity="0" />
                          <plugin instance="composite" />
                          <body name="link_10" pos="-0.000441179 0.00156015 0.0479454" quat="0.994979 -0.0314896 -0.0122296 -0.0942127">
                            <inertial pos="0 0 0" mass="0.0025" diaginertia="1e-6 1e-6 1e-6" />
                            <joint name="joint_9" pos="0 0 -0.024" type="ball" />
                            <geom name="link_10_collision" size="0.002 0.024" type="cylinder" group="3" />
                            <geom name="sphere_10_collision" size="0.002" pos="0 0 0.024" group="3" />
                            <geom name="link_10_vis" size="0.002 0.024" type="cylinder" contype="0" conaffinity="0" />
                            <geom name="sphere_10_vis" size="0.002" pos="0 0 0.024" contype="0" conaffinity="0" />
                            <plugin instance="composite" />
                            <body name="link_11" pos="0.00114853 0.00243771 0.0478493" quat="0.994284 -0.0528353 0.0192331 -0.0907645">
                              <inertial pos="0 0 0" mass="0.0025" diaginertia="1e-6 1e-6 1e-6" />
                              <joint name="joint_10" pos="0 0 -0.024" type="ball" />
                              <geom name="link_11_collision" size="0.002 0.024" type="cylinder" group="3" />
                              <geom name="sphere_11_collision" size="0.002" pos="0 0 0.024" group="3" />
                              <geom name="link_11_vis" size="0.002 0.024" type="cylinder" contype="0" conaffinity="0" />
                              <geom name="sphere_11_vis" size="0.002" pos="0 0 0.024" contype="0" conaffinity="0" />
                              <plugin instance="composite" />
                              <body name="link_12" pos="0.00319193 0.00397127 0.0474547" quat="0.991985 -0.0875655 0.0610639 -0.0676033">
                                <inertial pos="0 0 0" mass="0.0025" diaginertia="1e-6 1e-6 1e-6" />
                                <joint name="joint_11" pos="0 0 -0.024" type="ball" />
                                <geom name="link_12_collision" size="0.002 0.024" type="cylinder" group="3" />
                                <geom name="sphere_12_collision" size="0.002" pos="0 0 0.024" group="3" />
                                <geom name="link_12_vis" size="0.002 0.024" type="cylinder" contype="0" conaffinity="0" />
                                <geom name="sphere_12_vis" size="0.002" pos="0 0 0.024" contype="0" conaffinity="0" />
                                <plugin instance="composite" />
                                <body name="link_13" pos="0.00477094 0.00576188 0.0468049" quat="0.986645 -0.125566 0.0955868 -0.040351">
                                  <inertial pos="0 0 0" mass="0.0025" diaginertia="1e-6 1e-6 1e-6" />
                                  <joint name="joint_12" pos="0 0 -0.024" type="ball" />
                                  <geom name="link_13_collision" size="0.002 0.024" type="cylinder" group="3" />
                                  <geom name="sphere_13_collision" size="0.002" pos="0 0 0.024" group="3" />
                                  <geom name="link_13_vis" size="0.002 0.024" type="cylinder" contype="0" conaffinity="0" />
                                  <geom name="sphere_13_vis" size="0.002" pos="0 0 0.024" contype="0" conaffinity="0" />
                                  <plugin instance="composite" />
                                  <body name="link_14" pos="0.005839 0.00733455 0.0460941" quat="0.979848 -0.157594 0.122011 -0.0132488">
                                    <inertial pos="0 0 0" mass="0.0025" diaginertia="1e-6 1e-6 1e-6" />
                                    <joint name="joint_13" pos="0 0 -0.024" type="ball" />
                                    <geom name="link_14_collision" size="0.002 0.024" type="cylinder" group="3" />
                                    <geom name="sphere_14_collision" size="0.002" pos="0 0 0.024" group="3" />
                                    <geom name="link_14_vis" size="0.002 0.024" type="cylinder" contype="0" conaffinity="0" />
                                    <geom name="sphere_14_vis" size="0.002" pos="0 0 0.024" contype="0" conaffinity="0" />
                                    <plugin instance="composite" />
                                    <body name="link_15" pos="0.00648458 0.00806215 0.0456562" quat="0.975213 -0.170653 0.140422 0.0109129">
                                      <inertial pos="0 0 0" mass="0.0025" diaginertia="1e-6 1e-6 1e-6" />
                                      <joint name="joint_14" pos="0 0 -0.024" type="ball" />
                                      <geom name="link_15_collision" size="0.002 0.024" type="cylinder" group="3" />
                                      <geom name="sphere_15_collision" size="0.002" pos="0 0 0.024" group="3" />
                                      <geom name="link_15_vis" size="0.002 0.024" type="cylinder" contype="0" conaffinity="0" />
                                      <geom name="sphere_15_vis" size="0.002" pos="0 0 0.024" contype="0" conaffinity="0" />
                                      <plugin instance="composite" />
                                      <body name="link_16" pos="0.00662934 0.0075781 0.0457874" quat="0.976219 -0.157324 0.146215 0.0294472">
                                        <inertial pos="0 0 0" mass="0.0025" diaginertia="1e-6 1e-6 1e-6" />
                                        <joint name="joint_15" pos="0 0 -0.024" type="ball" />
                                        <geom name="link_16_collision" size="0.002 0.024" type="cylinder" group="3" />
                                        <geom name="sphere_16_collision" size="0.002" pos="0 0 0.024" group="3" />
                                        <geom name="link_16_vis" size="0.002 0.024" type="cylinder" contype="0" conaffinity="0" />
                                        <geom name="sphere_16_vis" size="0.002" pos="0 0 0.024" contype="0" conaffinity="0" />
                                        <plugin instance="composite" />
                                        <body name="link_17" pos="0.00635258 0.00595334 0.0463669" quat="0.981986 -0.120488 0.139748 0.0407034">
                                          <inertial pos="0 0 0" mass="0.0025" diaginertia="1e-6 1e-6 1e-6" />
                                          <joint name="joint_16" pos="0 0 -0.024" type="ball" />
                                          <geom name="link_17_collision" size="0.002 0.024" type="cylinder" group="3" />
                                          <geom name="sphere_17_collision" size="0.002" pos="0 0 0.024" group="3" />
                                          <geom name="link_17_vis" size="0.002 0.024" type="cylinder" contype="0" conaffinity="0" />
                                          <geom name="sphere_17_vis" size="0.002" pos="0 0 0.024" contype="0" conaffinity="0" />
                                          <plugin instance="composite" />
                                          <body name="link_18" pos="0.00575653 0.003482 0.047038" quat="0.988962 -0.06784 0.124269 0.0436973">
                                            <inertial pos="0 0 0" mass="0.0025" diaginertia="1e-6 1e-6 1e-6" />
                                            <joint name="joint_17" pos="0 0 -0.024" type="ball" />
                                            <geom name="link_18_collision" size="0.002 0.024" type="cylinder" group="3" />
                                            <geom name="sphere_18_collision" size="0.002" pos="0 0 0.024" group="3" />
                                            <geom name="link_18_vis" size="0.002 0.024" type="cylinder" contype="0" conaffinity="0" />
                                            <geom name="sphere_18_vis" size="0.002" pos="0 0 0.024" contype="0" conaffinity="0" />
                                            <plugin instance="composite" />
                                            <body name="link_19" pos="0.00550013 0.00141785 0.0473194" quat="0.992157 -0.0253624 0.116454 0.0376818">
                                              <inertial pos="0 0 0" mass="0.0025" diaginertia="1e-6 1e-6 1e-6" />
                                              <joint name="joint_18" pos="0 0 -0.024" type="ball" />
                                              <geom name="link_19_collision" size="0.002 0.024" type="cylinder" group="3" />
                                              <geom name="sphere_19_collision" size="0.002" pos="0 0 0.024" group="3" />
                                              <geom name="link_19_vis" size="0.002 0.024" type="cylinder" contype="0" conaffinity="0" />
                                              <geom name="sphere_19_vis" size="0.002" pos="0 0 0.024" contype="0" conaffinity="0" />
                                              <plugin instance="composite" />
                                              <body name="link_20" pos="0.00534656 -0.00101358 0.0473769" quat="0.993097 0.0243171 0.111486 0.027151">
                                                <inertial pos="0 0 0" mass="0.0025" diaginertia="1e-6 1e-6 1e-6" />
                                                <joint name="joint_19" pos="0 0 -0.024" type="ball" />
                                                <geom name="link_20_collision" size="0.002 0.024" type="cylinder" group="3" />
                                                <geom name="sphere_20_collision" size="0.002" pos="0 0 0.024" group="3" />
                                                <geom name="link_20_vis" size="0.002 0.024" type="cylinder" contype="0" conaffinity="0" />
                                                <geom name="sphere_20_vis" size="0.002" pos="0 0 0.024" contype="0" conaffinity="0" />
                                                <plugin instance="composite" />
                                                <body name="cable_connection_1" pos="1.18118e-06 -3.36725e-07 0.0240001" quat="0.773544 0.0588014 -0.629752 -0.039807">
                                                  <inertial pos="0 0 0" mass="0.01" diaginertia="4e-4 4e-4 4e-4" />
                                                  <joint name="joint_connection_end_1" class="cable_default" pos="0 0 0" type="ball" />
                                                  <geom name="collision_0" class="world_default" size="0.001 0.00367636" pos="0.00367636 -0.00425 0" quat="0.673802 0.214463 0.673798 -0.214461" type="cylinder" group="3" />
                                                  <geom name="collision_1" class="world_default" size="0.001 0.00367636" pos="0.00367636 0.00425 0" quat="0.673802 -0.214463 0.673798 0.214461" type="cylinder" group="3" />
                                                  <geom name="visual_0" class="world_default" size="0.001 0.00367636" pos="0.00367636 -0.00425 0" quat="0.673802 0.214463 0.673798 -0.214461" type="cylinder" contype="0" conaffinity="0" />
                                                  <geom name="visual_1" class="world_default" size="0.001 0.00367636" pos="0.00367636 0.00425 0" quat="0.673802 -0.214463 0.673798 0.214461" type="cylinder" contype="0" conaffinity="0" />
                                                  <plugin instance="composite" />
                                                  <body name="sc_plug_link" pos="0.0520001 -2.50452e-10 -3.85925e-08" quat="1 -9.69236e-08 -4.66151e-08 -3.51934e-09">
                                                    <inertial pos="-0.0113552 5.95326e-05 9.66547e-06" quat="0.000666424 0.706845 -0.000660251 0.707368" mass="0.04" diaginertia="8.92011e-06 7.22349e-06 2.15571e-06" />
                                                    <geom name="housing blue_predeterminado005_collider_box" class="world_default" size="0.006861 0.0045 0.00365" pos="0.002539 0.006344 4e-06" type="box" group="3" />
                                                    <geom name="housing blue_predeterminado005_collider_box.001" class="world_default" size="0.006861 0.0045 0.00365" pos="0.002539 -0.006344 4e-06" type="box" group="3" />
                                                    <geom name="cube002_collider_box" class="world_default" size="0.006275 0.0125 0.00505" pos="-0.010291 0 0" type="box" group="3" />
                                                    <geom name="cylinder011_collider_cylinder" class="world_default" size="0.0029 0.014605" pos="-0.031147 -0.00635 0" quat="0.707107 0 0.707107 0" type="cylinder" group="3" />
                                                    <geom name="cylinder005_collider_cylinder" class="world_default" size="0.0029 0.015799" pos="-0.029953 0.00635 0" quat="0.707107 0 0.707107 0" type="cylinder" group="3" />
                                                    <geom name="ferula_predeterminado005_collider_cylinder" class="world_default" size="0.00125 0.007" pos="0.00465 -0.00635 0" quat="0.707107 0 0.707107 0" type="cylinder" group="3" />
                                                    <geom name="ferula_predeterminado003_collider_cylinder" class="world_default" size="0.00125 0.007" pos="0.00465 0.00635 0" quat="0.707107 0 0.707107 0" type="cylinder" group="3" />
                                                    <geom name="side_box_collision" class="world_default" size="0.002125 0.00081 0.0005" pos="0.00146 -0.00632 0.0042" type="box" group="3" />
                                                    <geom name="side_box_collision_2" class="world_default" size="0.002125 0.00081 0.0005" pos="0.00146 0.00632 0.0042" type="box" group="3" />
                                                    <geom name="sc_plug_visual" class="world_default" type="mesh" contype="0" conaffinity="0" material="material_64e61b65f045552ba26a6ad52be1054f951feb31fe90869f7d202e8045dc22e6_sc_plug_visual_merged_0" mesh="64e61b65f045552ba26a6ad52be1054f951feb31fe90869f7d202e8045dc22e6_sc_plug_visual_merged_0" />
                                                    <plugin instance="composite" />
                                                    <body name="sc_tip_link" pos="0.01165 -3.5659e-08 1.72361e-07" quat="0.499998 -0.5 0.500001 -0.5">
                                                      <inertial pos="0 0 0" mass="0.001" diaginertia="1e-06 1e-06 1e-06" />
                                                    </body>
                                                  </body>
                                                </body>
                                              </body>
                                            </body>
                                          </body>
                                        </body>
                                      </body>
                                    </body>
                                  </body>
                                </body>
                              </body>
                            </body>
                          </body>
                        </body>
                      </body>
                    </body>
                  </body>
                </body>
              </body>
            </body>
          </body>
        </body>
        
      </body>
</body>
    </body>
                    <body name="gripper/hande_finger_link_l" gravcomp="1" pos="0 0 0">
                      <inertial pos="0 0 0" mass="0.001" diaginertia="0.0001 9e-05 3e-05" />
                      <joint name="gripper/left_finger_joint" class="robot_unused" pos="0 0 0" axis="1 0 0" type="slide" limited="true" range="0 0.025" />
                      <geom name="gripper/hande_finger_link_l_fixed_joint_lump__finger_collider_box_collision" class="robot_unused" size="0.0039195 0.0105 0.014311" pos="0.007595 -1e-05 0.138138" type="box" group="3" />
                      <geom name="gripper/hande_finger_link_l_fixed_joint_lump__finger_collider_box001_collision_1" class="robot_unused" size="0.003 0.0105 0.010749" pos="0.003 -1e-05 0.16145" type="box" group="3" />
                      <geom name="gripper/hande_finger_link_l_fixed_joint_lump__finger_collider_box002_collision_2" class="robot_unused" size="0.0221595 0.00375 0.0019745" pos="-0.010646 -0.015 0.124725" type="box" group="3" />
                      <geom name="gripper/hande_finger_link_l_fixed_joint_lump__finger_collider_box003_collision_3" class="robot_unused" size="0.0086935 0.0092095 0.0046355" pos="0.002046 -0.00954 0.129064" type="box" group="3" />
                      <geom name="gripper/hande_finger_link_l_fixed_joint_lump__hande_finger_visual_visual" class="robot_unused" pos="-0.025 0 0" quat="1 0 0 0" type="mesh" contype="0" conaffinity="0" material="material_354908445af88fcf1366e0e4d2bd23726354cdb419dd151b3c01461be6e77331_hande_finger_visual_Finger.001" mesh="354908445af88fcf1366e0e4d2bd23726354cdb419dd151b3c01461be6e77331_hande_finger_visual_Finger.001" />
                    </body>
                    <body name="gripper/hande_finger_link_r" gravcomp="1" pos="0 0 0">
                      <inertial pos="0 0 0" mass="0.001" diaginertia="0.0001 9e-05 3e-05" />
                      <joint name="gripper/right_finger_joint" class="robot_unused" pos="0 0 0" axis="-1 0 0" type="slide" limited="true" range="0 0.025" />
                      <geom name="gripper/hande_finger_link_r_fixed_joint_lump__finger_collider_box_collision" class="robot_unused" size="0.0039195 0.0105 0.014311" pos="-0.007595 -1e-05 0.138138" type="box" group="3" />
                      <geom name="gripper/hande_finger_link_r_fixed_joint_lump__finger_collider_box001_collision_1" class="robot_unused" size="0.003 0.0105 0.010749" pos="-0.003 -1e-05 0.16145" type="box" group="3" />
                      <geom name="gripper/hande_finger_link_r_fixed_joint_lump__finger_collider_box002_collision_2" class="robot_unused" size="0.0221595 0.00375 0.0019745" pos="0.010646 -0.015 0.124725" type="box" group="3" />
                      <geom name="gripper/hande_finger_link_r_fixed_joint_lump__finger_collider_box003_collision_3" class="robot_unused" size="0.0086935 0.0092095 0.0046355" pos="-0.002046 -0.00954 0.129064" type="box" group="3" />
                      <geom name="gripper/hande_finger_link_r_fixed_joint_lump__hande_finger_visual_visual" class="robot_unused" pos="0.025 0 0" quat="1.13268e-05 0 0 1" type="mesh" contype="0" conaffinity="0" material="material_354908445af88fcf1366e0e4d2bd23726354cdb419dd151b3c01461be6e77331_hande_finger_visual_Finger.001" mesh="354908445af88fcf1366e0e4d2bd23726354cdb419dd151b3c01461be6e77331_hande_finger_visual_Finger.001" />
                    </body>
                  </body>
                  <body name="left_camera/sensor_link" gravcomp="1" pos="-0.100517 -0.0580326 -0.00893589" quat="0.766321 0.157559 -0.588018 0.205335">
                    <inertial pos="0 0 0" mass="0.001" diaginertia="1e-06 1e-06 1e-06" />
                    <camera name="left_camera" class="robot_unused" pos="0 0 0" quat="0.5 0.5 -0.5 -0.5" fovy="44.982" resolution="1152 1024" />
                    <body name="left_camera/optical" gravcomp="1" pos="0 0 0" quat="0.499998 -0.5 0.500002 -0.5">
                      <inertial pos="0 0 0" mass="0.001" diaginertia="1e-06 1e-06 1e-06" />
                    </body>
                  </body>
                  <body name="right_camera/sensor_link" gravcomp="1" pos="0.100517 -0.0580326 -0.00893588" quat="0.205335 0.588018 -0.157559 0.766321">
                    <inertial pos="0 0 0" mass="0.001" diaginertia="1e-06 1e-06 1e-06" />
                    <camera name="right_camera" class="robot_unused" pos="0 0 0" quat="0.5 0.5 -0.5 -0.5" fovy="44.982" resolution="1152 1024" />
                    <body name="right_camera/optical" gravcomp="1" pos="0 0 0" quat="0.499998 -0.5 0.500002 -0.5">
                      <inertial pos="0 0 0" mass="0.001" diaginertia="1e-06 1e-06 1e-06" />
                    </body>
                  </body>
                </body>
              </body>
            </body>
          </body>
        </body>
      </body>
    </body>
  </worldbody>

  <contact>
    <exclude name="tabletop_shoulder_link" body1="tabletop" body2="shoulder_link" />
    <exclude body1="tabletop" body2="shoulder_link" />
    <exclude body1="gripper/hande_finger_link_l" body2="gripper/hande_finger_link_r" />
  </contact>

  
  <actuator>
    <position name="shoulder_pan_joint_motor" joint="shoulder_pan_joint" kp="500" ctrllimited="true" ctrlrange="-6.28319 6.28319" />
    <position name="shoulder_lift_joint_motor" joint="shoulder_lift_joint" kp="500" ctrllimited="true" ctrlrange="-6.28319 6.28319" />
    <position name="elbow_joint_motor" joint="elbow_joint" kp="500" ctrllimited="true" ctrlrange="-3.14159 3.14159" />
    <position name="wrist_1_joint_motor" joint="wrist_1_joint" kp="500" ctrllimited="true" ctrlrange="-6.28319 6.28319" />
    <position name="wrist_2_joint_motor" joint="wrist_2_joint" kp="500" ctrllimited="true" ctrlrange="-6.28319 6.28319" />
    <position name="wrist_3_joint_motor" joint="wrist_3_joint" kp="500" ctrllimited="true" ctrlrange="-6.28319 6.28319" />
    <position name="gripper/left_finger_joint_motor" joint="gripper/left_finger_joint" kp="100" ctrllimited="true" ctrlrange="0 0.025" />
  </actuator>

  <equality>
    <joint joint1="gripper/left_finger_joint" joint2="gripper/right_finger_joint" polycoef="0 1 0 0 0" />
  </equality>

  <sensor>
    <force name="AtiForceTorqueSensor_force" site="AtiForceTorqueSensor" />
    <torque name="AtiForceTorqueSensor_torque" site="AtiForceTorqueSensor" />
  </sensor>

  </mujoco>